Workbook

Sheet INSTRUCCIONES
A2: Planilla "Insumos"
A3: Concepto: En esta planilla se cargan todos los costos de los insumos utilizados para fabricar que luego utilizaremos en la planilla "Recetas". Es clave que se chequee que la cantidad de unidades por bulto este bien expresada, por ejemplo 3200 grs si es una barra de queso de3,2 kg
A4: Campo de planilla | B4: Completar / No completar | C4: Instrucciones
A5: Insumos | B5: Completar | C5: 1- Completar el nombre del insumo IMPORTANTE: No cambiar el orden. De agregar insumos van al final
A6: Tipo de costo | B6: Completar | C6: 2- Seleccionar el tipo de costo al que se hace alusión
A7: Proveedor | B7: Completar | C7: 3-Completar el nombre del proveedor
A8: Cantidad de Unidades por bulto | B8: Completar | C8: 4- Completar la cantidad de unidades por bulto. Por ej: Si una barra de queso trae 2,3 kg, completar con 2300 grs. Si comprás por unidad, poné cuántas unidades trae el bulto (por ej. 30 huevos).
A9: U. de medida bulto | B9: Completar | C9: 5- Seleccioná si son gramos (Grs), mililitros (Ml) o unidades (Un). Si comprás por unidad (huevos, limones), elegí Un y cargá unidades en lugar de gramos.
A10: Costo del bulto | B10: Completar | C10: 6- Completar con el costo del bulto. Ojo con el IVA: mirá el bloque "IVA: cómo cargar según tu caso" al final de esta hoja.
A11: Costo por unidad | B11: No completar | C11: 7- Se completa solo. En Insumos se marca en rojo el costo que falta de un insumo que ya estás usando en una receta: completá el costo del bulto y la cantidad por bulto.
A13: Planilla "Recetas"
A14: Concepto: Acá se cargan todas las recetas que queremos costear. Prestar atención respecto si es necesario o no cargar cada campo.
A15: Campo de planilla | B15: Completar / No completar | C15: Planilla "Recetas"
A16: Receta número | B16: No completar | C16: El es número de receta cargada. Sirve para Buscarla luego
A17: Nombre de la receta | B17: Completar | C17: Escribir el nombre de la preparación
A18: Tipo de producto | B18: Completar | C18: Seleccionar el tipo de producto que se quiere costear
A19: Cantidad de porciones | B19: Completar | C19: Indicar las porciones que salen de esa preparación
A20: Precio de venta al público | B20: Completar | C20: Precio de venta final, tal cual está en la carta (con IVA incluido).
A21: Gramos por receta | B21: No completar | C21: Se calcula solo. Es el peso de la receta en gramos. No suma los insumos que van por unidad (Un).
A22: Gramos por porción | B22: No completar | C22: Se calcula solo. Es el peso de la porción en gramos. No suma los insumos que van por unidad (Un).
A23: Insumo | B23: Completar | C23: Seleccionar del desplegable el insumo que fue previamente cargado. No escribir, solo seleccionar. La columna "Unidad" (a la derecha de la receta) se completa sola: muestra si el insumo va en Grs, Ml o Un.
A24: Peso bruto | B24: No completar | C24: Se calcula solo. Es el peso bruto con la merma incluida: lo que tenés que comprar para que te quede el peso neto.
A25: Merma en % | B25: No completar | C25: No completar: se trae sola de la hoja 'Mermas por producto'. Si la merma de tu insumo es otra, cambiala en esa hoja, no acá.
A26: Q Merma | B26: No completar | C26: Lo calcula solo. Son los gramos de merma que tiene la preparación
... A34: Peso total | B34: No completar | C34: Se calcula solo. Peso total de la preparación, bruto y neto. No suma los insumos que van por unidad (Un).
A36: Planilla "Margenes por producto"
A37: Concepto: Acá se resume la informacion clave de las recetas como costo, gramaje y el margen por producto en $ y en Precio/Costo
A38: Campo de planilla | B38: Completar / No completar | C38: Planilla "Recetas"
A39: Nº de receta | B39: No completar | C39: Es el número de receta cargada. Viene de la planilla "Recetas"
A40: Tipo de producto | B40: No completar | C40: Es el tipo de producto que estamos visualizando. Viene de la planilla "Recetas"
A41: Producto | B41: No completar | C41: Es el nombre del producto. Viene de la planilla "Recetas"
A42: Peso en grs | B42: No completar | C42: Es el gramaje que recibe el cliente neto de merma. Viene de la planilla "Recetas"
A43: Ud de medida | B43: No completar | C43: Unidad de medida. Si es una bebida poner Ml
A44: Costo | B44: No completar | C44: Es el costo unitario del producto. Viene de la planilla "Recetas"
A45: Precio de venta | B45: No completar | C45: Es el precio de venta al público, con IVA. Viene de la planilla "Recetas"
A46: Ganancia por unidad | B46: No completar | C46: Es una medida calculada: precio de venta sin IVA (columna "Precio sin IVA") menos el costo unitario.
A47: Ventas/Costos | B47: No completar | C47: Es una métrica de desempeño económico: precio de venta sin IVA dividido el costo. Por ejemplo, 3 quiere decir que vendés a 3 veces lo que te cuesta.
A48: Activo/No activo | B48: Completar | C48: Se selecciona segun el producto este o no activo
A50: Planilla "Mermas por producto "
A51: Concepto: Esta base de datos contiene las mermas estandar de casi 300 productos
...

Sheet Insumos 
A1: Insumos | B1: Tipo de Costo | C1: Proveedor | D1: Cantidad de Unidades por bulto (en gramos, mililitros o unidades) | E1: U. de medida bulto | F1: Costo del bulto | G1: Costo por unidad
A2: Aceite de oliva | G2: =IFERROR(F2/D2, "-") -> -
A3: Aceite de sesamo | G3: =IFERROR(F3/D3, "-") -> -
A4: Aceite mezcla | G4: =IFERROR(F4/D4, "-") -> -
A5: Aceite para freir | G5: =IFERROR(F5/D5, "-") -> -
A6: Aceitunas descarozadas | G6: =IFERROR(F6/D6, "-") -> -
A7: Acelga | G7: =IFERROR(F7/D7, "-") -> -
A8: Aceto balsamico | G8: =IFERROR(F8/D8, "-") -> -
A9: Achicoria | G9: =IFERROR(F9/D9, "-") -> -
A10: Agua | G10: =IFERROR(F10/D10, "-") -> -
A11: Agua tonica | G11: =IFERROR(F11/D11, "-") -> -
A12: Ajo | G12: =IFERROR(F12/D12, "-") -> -
A13: Ajo pasta | G13: =IFERROR(F13/D13, "-") -> -
... A155: Limon | G155: =IFERROR(F155/D155, "-") -> -
G156: =IFERROR(F156/D156, "-") -> -
A157: Lomo (vacuno) | G157: =IFERROR(F157/D157, "-") -> -
A158: Lomo de cerdo | G158: =IFERROR(F158/D158, "-") -> -
G159: =IFERROR(F159/D159, "-") -> -
A160: Malta | G160: =IFERROR(F160/D160, "-") -> -
A161: Mandarina | G161: =IFERROR(F161/D161, "-") -> -
A162: Mandioca | G162: =IFERROR(F162/D162, "-") -> -
G163: =IFERROR(F163/D163, "-") -> -
A164: Mani aceite | G164: =IFERROR(F164/D164, "-") -> -
A165: Mani salado | G165: =IFERROR(F165/D165, "-") -> -
A166: Manteca | G166: =IFERROR(F166/D166, "-") -> -
A167: Manzana | G167: =IFERROR(F167/D167, "-") -> -
A168: Martini dry | G168: =IFERROR(F168/D168, "-") -> -
A169: Masa madre | G169: =IFERROR(F169/D169, "-") -> -
A170: Mascarpone | G170: =IFERROR(F170/D170, "-") -> -
A171: Mayonesa | G171: =IFERROR(F171/D171, "-") -> -
A172: Mejillones | G172: =IFERROR(F172/D172, "-") -> -
A173: Melón | G173: =IFERROR(F173/D173, "-") -> -
A174: Membrillo | G174: =IFERROR(F174/D174, "-") -> -
A175: Menta | G175: =IFERROR(F175/D175, "-") -> -
... A183: Mostaza dijon | G183: =IFERROR(F183/D183, "-") -> -
G184: =IFERROR(F184/D184, "-") -> -
A185: Mozzarella | G185: =IFERROR(F185/D185, "-") -> -
A186: Nabiza | G186: =IFERROR(F186/D186, "-") -> -
A187: Nabo | G187: =IFERROR(F187/D187, "-") -> -
A188: Naranja | G188: =IFERROR(F188/D188, "-") -> -
...

Sheet Recetas
A1: Costos de recetas
A3: Receta Nº 1
A4: Nombre de la receta | E4: Precio de venta al publico | G4: 0
A5: Tipo de producto | E5: Gramos por receta | G5: =E15 -> 0
A6: Cantidad de porciones | B6: Completar con número | E6: Gramos por porción | G6: =IFERROR(G5/B6, 0) -> 0
A7: Insumo | B7: Peso Bruto (Grs o Un) | C7: Merma en % | D7: Q Merma (Grs) | E7: Peso neto (Grs o Un) | F7: Costo Grs | G7: Costo real | H7: Distribucion | I7: Unidad
B8: =E8/(100%-C8) -> 0 | C8: =IF(I8="Un",0,IFERROR(VLOOKUP(A8,'Mermas por producto'!$A$2:$B$313,2,0),0)) -> 0 | D8: =B8*C8 -> 0 | F8: =IFERROR(VLOOKUP(A8,'Insumos '!A:G,7,0),"") | G8: =IFERROR(B8*F8, 0) -> 0 | H8: =IFERROR(G8/$G$15, 0) -> 0 | I8: =IFERROR(TRIM(VLOOKUP(A8,'Insumos '!$A$2:$E$313,5,0)&""),"")
B9: =E9/(100%-C9) -> 0 | C9: =IF(I9="Un",0,IFERROR(VLOOKUP(A9,'Mermas por producto'!$A$2:$B$313,2,0),0)) -> 0 | D9: =B9*C9 -> 0 | F9: =IFERROR(VLOOKUP(A9,'Insumos '!A:G,7,0),"") | G9: =IFERROR(B9*F9, 0) -> 0 | H9: =IFERROR(G9/$G$15, 0) -> 0 | I9: =IFERROR(TRIM(VLOOKUP(A9,'Insumos '!$A$2:$E$313,5,0)&""),"")
B10: =E10/(100%-C10) -> 0 | C10: =IF(I10="Un",0,IFERROR(VLOOKUP(A10,'Mermas por producto'!$A$2:$B$313,2,0),0)) -> 0 | D10: =B10*C10 -> 0 | F10: =IFERROR(VLOOKUP(A10,'Insumos '!A:G,7,0),"") | G10: =IFERROR(B10*F10, 0) -> 0 | H10: =IFERROR(G10/$G$15, 0) -> 0 | I10: =IFERROR(TRIM(VLOOKUP(A10,'Insumos '!$A$2:$E$313,5,0)&""),"")
B11: =E11/(100%-C11) -> 0 | C11: =IF(I11="Un",0,IFERROR(VLOOKUP(A11,'Mermas por producto'!$A$2:$B$313,2,0),0)) -> 0 | D11: =B11*C11 -> 0 | F11: =IFERROR(VLOOKUP(A11,'Insumos '!A:G,7,0),"") | G11: =IFERROR(B11*F11, 0) -> 0 | H11: =IFERROR(G11/$G$15, 0) -> 0 | I11: =IFERROR(TRIM(VLOOKUP(A11,'Insumos '!$A$2:$E$313,5,0)&""),"")
B12: =E12/(100%-C12) -> 0 | C12: =IF(I12="Un",0,IFERROR(VLOOKUP(A12,'Mermas por producto'!$A$2:$B$313,2,0),0)) -> 0 | D12: =B12*C12 -> 0 | F12: =IFERROR(VLOOKUP(A12,'Insumos '!A:G,7,0),"") | G12: =IFERROR(B12*F12, 0) -> 0 | H12: =IFERROR(G12/$G$15, 0) -> 0 | I12: =IFERROR(TRIM(VLOOKUP(A12,'Insumos '!$A$2:$E$313,5,0)&""),"")
B13: =E13/(100%-C13) -> 0 | C13: =IF(I13="Un",0,IFERROR(VLOOKUP(A13,'Mermas por producto'!$A$2:$B$313,2,0),0)) -> 0 | D13: =B13*C13 -> 0 | F13: =IFERROR(VLOOKUP(A13,'Insumos '!$A$2:$G$313,7,0),"") | G13: =IFERROR(B13*F13, 0) -> 0 | H13: =IFERROR(G13/$G$15, 0) -> 0 | I13: =IFERROR(TRIM(VLOOKUP(A13,'Insumos '!$A$2:$E$313,5,0)&""),"")
B14: =E14/(100%-C14) -> 0 | C14: =IF(I14="Un",0,IFERROR(VLOOKUP(A14,'Mermas por producto'!$A$2:$B$313,2,0),0)) -> 0 | D14: =B14*C14 -> 0 | F14: =IFERROR(VLOOKUP(A14,'Insumos '!A:G,7,0),"") | G14: =IFERROR(B14*F14, 0) -> 0 | H14: =IFERROR(G14/$G$15, 0) -> 0 | I14: =IFERROR(TRIM(VLOOKUP(A14,'Insumos '!$A$2:$E$313,5,0)&""),"")
A15: Peso total | B15: =SUMIF(I8:I14,"<>Un",B8:B14) -> 0 | C15: grs | D15: =SUMIF(I8:I14,"<>Un",D8:D14) -> 0 | E15: =SUMIF(I8:I14,"<>Un",E8:E14) -> 0 | F15: Costo Total Preparación | G15: =SUM(G8:G14) -> 0 | H15: =SUM(H8:H14) -> 0
F16: Costo Grs | G16: =IFERROR(G15/E15, 0) -> 0
F17: Costo Porción | G17: =IFERROR(G15/B6, 0) -> 0
A19: Receta Nº 2
A20: Nombre de la receta | E20: Precio de venta al publico | G20: 0
A21: Tipo de producto | E21: Gramos por receta | G21: =E31 -> 0
A22: Cantidad de porciones | B22: Completar con número | E22: Gramos por porción | G22: =IFERROR(G21/B22, 0) -> 0
A23: Insumo | B23: Peso Bruto (Grs o Un) | C23: Merma en % | D23: Q Merma (Grs) | E23: Peso neto (Grs o Un) | F23: Costo Grs | G23: Costo real | H23: Distribucion | I23: Unidad
B24: =E24/(100%-C24) -> 0 | C24: =IF(I24="Un",0,IFERROR(VLOOKUP(A24,'Mermas por producto'!$A$2:$B$313,2,0),0)) -> 0 | D24: =B24*C24 -> 0 | F24: =IFERROR(VLOOKUP(A24,'Insumos '!A:G,7,0),"") | G24: =IFERROR(B24*F24, 0) -> 0 | H24: =IFERROR(G24/$G$31, 0) -> 0 | I24: =IFERROR(TRIM(VLOOKUP(A24,'Insumos '!$A$2:$E$313,5,0)&""),"")
B25: =E25/(100%-C25) -> 0 | C25: =IF(I25="Un",0,IFERROR(VLOOKUP(A25,'Mermas por producto'!$A$2:$B$313,2,0),0)) -> 0 | D25: =B25*C25 -> 0 | F25: =IFERROR(VLOOKUP(A25,'Insumos '!A:G,7,0),"") | G25: =IFERROR(B25*F25, 0) -> 0 | H25: =IFERROR(G25/$G$31, 0) -> 0 | I25: =IFERROR(TRIM(VLOOKUP(A25,'Insumos '!$A$2:$E$313,5,0)&""),"")
B26: =E26/(100%-C26) -> 0 | C26: =IF(I26="Un",0,IFERROR(VLOOKUP(A26,'Mermas por producto'!$A$2:$B$313,2,0),0)) -> 0 | D26: =B26*C26 -> 0 | F26: =IFERROR(VLOOKUP(A26,'Insumos '!A:G,7,0),"") | G26: =IFERROR(B26*F26, 0) -> 0 | H26: =IFERROR(G26/$G$31, 0) -> 0 | I26: =IFERROR(TRIM(VLOOKUP(A26,'Insumos '!$A$2:$E$313,5,0)&""),"")
B27: =E27/(100%-C27) -> 0 | C27: =IF(I27="Un",0,IFERROR(VLOOKUP(A27,'Mermas por producto'!$A$2:$B$313,2,0),0)) -> 0 | D27: =B27*C27 -> 0 | F27: =IFERROR(VLOOKUP(A27,'Insumos '!A:G,7,0),"") | G27: =IFERROR(B27*F27, 0) -> 0 | H27: =IFERROR(G27/$G$31, 0) -> 0 | I27: =IFERROR(TRIM(VLOOKUP(A27,'Insumos '!$A$2:$E$313,5,0)&""),"")
B28: =E28/(100%-C28) -> 0 | C28: =IF(I28="Un",0,IFERROR(VLOOKUP(A28,'Mermas por producto'!$A$2:$B$313,2,0),0)) -> 0 | D28: =B28*C28 -> 0 | F28: =IFERROR(VLOOKUP(A28,'Insumos '!A:G,7,0),"") | G28: =IFERROR(B28*F28, 0) -> 0 | H28: =IFERROR(G28/$G$31, 0) -> 0 | I28: =IFERROR(TRIM(VLOOKUP(A28,'Insumos '!$A$2:$E$313,5,0)&""),"")
B29: =E29/(100%-C29) -> 0 | C29: =IF(I29="Un",0,IFERROR(VLOOKUP(A29,'Mermas por producto'!$A$2:$B$313,2,0),0)) -> 0 | D29: =B29*C29 -> 0 | F29: =IFERROR(VLOOKUP(A29,'Insumos '!$A$2:$G$313,7,0),"") | G29: =IFERROR(B29*F29, 0) -> 0 | H29: =IFERROR(G29/$G$31, 0) -> 0 | I29: =IFERROR(TRIM(VLOOKUP(A29,'Insumos '!$A$2:$E$313,5,0)&""),"")
B30: =E30/(100%-C30) -> 0 | C30: =IF(I30="Un",0,IFERROR(VLOOKUP(A30,'Mermas por producto'!$A$2:$B$313,2,0),0)) -> 0 | D30: =B30*C30 -> 0 | F30: =IFERROR(VLOOKUP(A30,'Insumos '!A:G,7,0),"") | G30: =IFERROR(B30*F30, 0) -> 0 | H30: =IFERROR(G30/$G$31, 0) -> 0 | I30: =IFERROR(TRIM(VLOOKUP(A30,'Insumos '!$A$2:$E$313,5,0)&""),"")
A31: Peso total | B31: =SUMIF(I24:I30,"<>Un",B24:B30) -> 0 | C31: grs | D31: =SUMIF(I24:I30,"<>Un",D24:D30) -> 0 | E31: =SUMIF(I24:I30,"<>Un",E24:E30) -> 0 | F31: Costo Total Preparación | G31: =SUM(G24:G30) -> 0 | H31: =SUM(H24:H30) -> 0
F32: Costo Grs | G32: =IFERROR(G31/E31, 0) -> 0
F33: Costo Porción | G33: =IFERROR(G31/B22, 0) -> 0
A35: Receta Nº 3
A36: Nombre de la receta | E36: Precio de venta al publico | G36: 0
A37: Tipo de producto | E37: Gramos por receta | G37: =E47 -> 0
A38: Cantidad de porciones | B38: Completar con número | E38: Gramos por porción | G38: =IFERROR(G37/B38, 0) -> 0
A39: Insumo | B39: Peso Bruto (Grs o Un) | C39: Merma en % | D39: Q Merma (Grs) | E39: Peso neto (Grs o Un) | F39: Costo Grs | G39: Costo real | H39: Distribucion | I39: Unidad
B40: =E40/(100%-C40) -> 0 | C40: =IF(I40="Un",0,IFERROR(VLOOKUP(A40,'Mermas por producto'!$A$2:$B$313,2,0),0)) -> 0 | D40: =B40*C40 -> 0 | F40: =IFERROR(VLOOKUP(A40,'Insumos '!A:G,7,0),"") | G40: =IFERROR(B40*F40, 0) -> 0 | H40: =IFERROR(G40/$G$47, 0) -> 0 | I40: =IFERROR(TRIM(VLOOKUP(A40,'Insumos '!$A$2:$E$313,5,0)&""),"")
B41: =E41/(100%-C41) -> 0 | C41: =IF(I41="Un",0,IFERROR(VLOOKUP(A41,'Mermas por producto'!$A$2:$B$313,2,0),0)) -> 0 | D41: =B41*C41 -> 0 | F41: =IFERROR(VLOOKUP(A41,'Insumos '!A:G,7,0),"") | G41: =IFERROR(B41*F41, 0) -> 0 | H41: =IFERROR(G41/$G$47, 0) -> 0 | I41: =IFERROR(TRIM(VLOOKUP(A41,'Insumos '!$A$2:$E$313,5,0)&""),"")
B42: =E42/(100%-C42) -> 0 | C42: =IF(I42="Un",0,IFERROR(VLOOKUP(A42,'Mermas por producto'!$A$2:$B$313,2,0),0)) -> 0 | D42: =B42*C42 -> 0 | F42: =IFERROR(VLOOKUP(A42,'Insumos '!A:G,7,0),"") | G42: =IFERROR(B42*F42, 0) -> 0 | H42: =IFERROR(G42/$G$47, 0) -> 0 | I42: =IFERROR(TRIM(VLOOKUP(A42,'Insumos '!$A$2:$E$313,5,0)&""),"")
B43: =E43/(100%-C43) -> 0 | C43: =IF(I43="Un",0,IFERROR(VLOOKUP(A43,'Mermas por producto'!$A$2:$B$313,2,0),0)) -> 0 | D43: =B43*C43 -> 0 | F43: =IFERROR(VLOOKUP(A43,'Insumos '!A:G,7,0),"") | G43: =IFERROR(B43*F43, 0) -> 0 | H43: =IFERROR(G43/$G$47, 0) -> 0 | I43: =IFERROR(TRIM(VLOOKUP(A43,'Insumos '!$A$2:$E$313,5,0)&""),"")
...

Sheet Margenes por producto 
A1: Nº de receta | B1: Tipos de producto | C1: Producto | D1: Peso en grs | E1: Ud de medida | F1: Costo | G1: Precio de venta | H1: Ganancia por unidad | I1: Ventas/Costos | J1: Activo / No activo | K1: Precio sin IVA | L1: Condición fiscal (elegí una)
A2: =Recetas!A3 -> Receta Nº 1 | B2: =Recetas!B5 -> 0 | C2: =Recetas!B4 -> 0 | D2: =Recetas!G6 -> 0 | E2: Grs | F2: =Recetas!G17 -> 0 | G2: =Recetas!G4 -> 0 | H2: =IFERROR(K2-F2,0) -> 0 | I2: =IFERROR(K2/F2,0) -> 0 | K2: =IF(G2="","",IF($L$2="Responsable inscripto",G2/1.21,G2)) -> 0 | L2: Responsable inscripto
A3: =Recetas!A19 -> Receta Nº 2 | B3: =Recetas!B21 -> 0 | C3: =Recetas!B20 -> 0 | D3: =Recetas!G22 -> 0 | E3: Grs | F3: =Recetas!G33 -> 0 | G3: =Recetas!G20 -> 0 | H3: =IFERROR(K3-F3,0) -> 0 | I3: =IFERROR(K3/F3,0) -> 0 | K3: =IF(G3="","",IF($L$2="Responsable inscripto",G3/1.21,G3)) -> 0
A4: =Recetas!A35 -> Receta Nº 3 | B4: =Recetas!B37 -> 0 | C4: =Recetas!B36 -> 0 | D4: =Recetas!G38 -> 0 | E4: Grs | F4: =Recetas!G49 -> 0 | G4: =Recetas!G36 -> 0 | H4: =IFERROR(K4-F4,0) -> 0 | I4: =IFERROR(K4/F4,0) -> 0 | K4: =IF(G4="","",IF($L$2="Responsable inscripto",G4/1.21,G4)) -> 0
A5: =Recetas!A51 -> Receta Nº 4 | B5: =Recetas!B53 -> 0 | C5: =Recetas!B52 -> 0 | D5: =Recetas!G54 -> 0 | E5: Grs | F5: =Recetas!G65 -> 0 | G5: =Recetas!G52 -> 0 | H5: =IFERROR(K5-F5,0) -> 0 | I5: =IFERROR(K5/F5,0) -> 0 | K5: =IF(G5="","",IF($L$2="Responsable inscripto",G5/1.21,G5)) -> 0
A6: =Recetas!A67 -> Receta Nº 5 | B6: =Recetas!B69 -> 0 | C6: =Recetas!B68 -> 0 | D6: =Recetas!G70 -> 0 | E6: Grs | F6: =Recetas!G81 -> 0 | G6: =Recetas!G68 -> 0 | H6: =IFERROR(K6-F6,0) -> 0 | I6: =IFERROR(K6/F6,0) -> 0 | K6: =IF(G6="","",IF($L$2="Responsable inscripto",G6/1.21,G6)) -> 0
A7: =Recetas!A83 -> Receta Nº 6 | B7: =Recetas!B85 -> 0 | C7: =Recetas!B84 -> 0 | D7: =Recetas!G86 -> 0 | E7: Grs | F7: =Recetas!G97 -> 0 | G7: =Recetas!G84 -> 0 | H7: =IFERROR(K7-F7,0) -> 0 | I7: =IFERROR(K7/F7,0) -> 0 | K7: =IF(G7="","",IF($L$2="Responsable inscripto",G7/1.21,G7)) -> 0
A8: =Recetas!A99 -> Receta Nº 7 | B8: =Recetas!B101 -> 0 | C8: =Recetas!B100 -> 0 | D8: =Recetas!G102 -> 0 | E8: Grs | F8: =Recetas!G113 -> 0 | G8: =Recetas!G100 -> 0 | H8: =IFERROR(K8-F8,0) -> 0 | I8: =IFERROR(K8/F8,0) -> 0 | K8: =IF(G8="","",IF($L$2="Responsable inscripto",G8/1.21,G8)) -> 0
A9: =Recetas!A115 -> Receta Nº 8 | B9: =Recetas!B117 -> 0 | C9: =Recetas!B116 -> 0 | D9: =Recetas!G118 -> 0 | E9: Grs | F9: =Recetas!G129 -> 0 | G9: =Recetas!G116 -> 0 | H9: =IFERROR(K9-F9,0) -> 0 | I9: =IFERROR(K9/F9,0) -> 0 | K9: =IF(G9="","",IF($L$2="Responsable inscripto",G9/1.21,G9)) -> 0
A10: =Recetas!A131 -> Receta Nº 9 | B10: =Recetas!B133 -> 0 | C10: =Recetas!B132 -> 0 | D10: =Recetas!G134 -> 0 | E10: Grs | F10: =Recetas!G145 -> 0 | G10: =Recetas!G132 -> 0 | H10: =IFERROR(K10-F10,0) -> 0 | I10: =IFERROR(K10/F10,0) -> 0 | K10: =IF(G10="","",IF($L$2="Responsable inscripto",G10/1.21,G10)) -> 0
A11: =Recetas!A147 -> Receta Nº 10 | B11: =Recetas!B149 -> 0 | C11: =Recetas!B148 -> 0 | D11: =Recetas!G150 -> 0 | E11: Grs | F11: =Recetas!G161 -> 0 | G11: =Recetas!G148 -> 0 | H11: =IFERROR(K11-F11,0) -> 0 | I11: =IFERROR(K11/F11,0) -> 0 | K11: =IF(G11="","",IF($L$2="Responsable inscripto",G11/1.21,G11)) -> 0
A12: =Recetas!A163 -> Receta Nº 11 | B12: =Recetas!B165 -> 0 | C12: =Recetas!B164 -> 0 | D12: =Recetas!G166 -> 0 | E12: Grs | F12: =Recetas!G177 -> 0 | G12: =Recetas!G164 -> 0 | H12: =IFERROR(K12-F12,0) -> 0 | I12: =IFERROR(K12/F12,0) -> 0 | K12: =IF(G12="","",IF($L$2="Responsable inscripto",G12/1.21,G12)) -> 0
A13: =Recetas!A179 -> Receta Nº 12 | B13: =Recetas!B181 -> 0 | C13: =Recetas!B180 -> 0 | D13: =Recetas!G182 -> 0 | E13: Grs | F13: =Recetas!G193 -> 0 | G13: =Recetas!G180 -> 0 | H13: =IFERROR(K13-F13,0) -> 0 | I13: =IFERROR(K13/F13,0) -> 0 | K13: =IF(G13="","",IF($L$2="Responsable inscripto",G13/1.21,G13)) -> 0
A14: =Recetas!A195 -> Receta Nº 13 | B14: =Recetas!B197 -> 0 | C14: =Recetas!B196 -> 0 | D14: =Recetas!G198 -> 0 | E14: Grs | F14: =Recetas!G209 -> 0 | G14: =Recetas!G196 -> 0 | H14: =IFERROR(K14-F14,0) -> 0 | I14: =IFERROR(K14/F14,0) -> 0 | K14: =IF(G14="","",IF($L$2="Responsable inscripto",G14/1.21,G14)) -> 0
A15: =Recetas!A211 -> Receta Nº 14 | B15: =Recetas!B213 -> 0 | C15: =Recetas!B212 -> 0 | D15: =Recetas!G214 -> 0 | E15: Grs | F15: =Recetas!G225 -> 0 | G15: =Recetas!G212 -> 0 | H15: =IFERROR(K15-F15,0) -> 0 | I15: =IFERROR(K15/F15,0) -> 0 | K15: =IF(G15="","",IF($L$2="Responsable inscripto",G15/1.21,G15)) -> 0
A16: =Recetas!A227 -> Receta Nº 15 | B16: =Recetas!B229 -> 0 | C16: =Recetas!B228 -> 0 | D16: =Recetas!G230 -> 0 | E16: Grs | F16: =Recetas!G241 -> 0 | G16: =Recetas!G228 -> 0 | H16: =IFERROR(K16-F16,0) -> 0 | I16: =IFERROR(K16/F16,0) -> 0 | K16: =IF(G16="","",IF($L$2="Responsable inscripto",G16/1.21,G16)) -> 0
A17: =Recetas!A243 -> Receta Nº 16 | B17: =Recetas!B245 -> 0 | C17: =Recetas!B244 -> 0 | D17: =Recetas!G246 -> 0 | E17: Grs | F17: =Recetas!G257 -> 0 | G17: =Recetas!G244 -> 0 | H17: =IFERROR(K17-F17,0) -> 0 | I17: =IFERROR(K17/F17,0) -> 0 | K17: =IF(G17="","",IF($L$2="Responsable inscripto",G17/1.21,G17)) -> 0
A18: =Recetas!A259 -> Receta Nº 17 | B18: =Recetas!B261 -> 0 | C18: =Recetas!B260 -> 0 | D18: =Recetas!G262 -> 0 | E18: Grs | F18: =Recetas!G273 -> 0 | G18: =Recetas!G260 -> 0 | H18: =IFERROR(K18-F18,0) -> 0 | I18: =IFERROR(K18/F18,0) -> 0 | K18: =IF(G18="","",IF($L$2="Responsable inscripto",G18/1.21,G18)) -> 0
A19: =Recetas!A275 -> Receta Nº 18 | B19: =Recetas!B277 -> 0 | C19: =Recetas!B276 -> 0 | D19: =Recetas!G278 -> 0 | E19: Grs | F19: =Recetas!G289 -> 0 | G19: =Recetas!G276 -> 0 | H19: =IFERROR(K19-F19,0) -> 0 | I19: =IFERROR(K19/F19,0) -> 0 | K19: =IF(G19="","",IF($L$2="Responsable inscripto",G19/1.21,G19)) -> 0
A20: =Recetas!A291 -> Receta Nº 19 | B20: =Recetas!B293 -> 0 | C20: =Recetas!B292 -> 0 | D20: =Recetas!G294 -> 0 | E20: Grs | F20: =Recetas!G305 -> 0 | G20: =Recetas!G292 -> 0 | H20: =IFERROR(K20-F20,0) -> 0 | I20: =IFERROR(K20/F20,0) -> 0 | K20: =IF(G20="","",IF($L$2="Responsable inscripto",G20/1.21,G20)) -> 0
A21: =Recetas!A307 -> Receta Nº 20 | B21: =Recetas!B309 -> 0 | C21: =Recetas!B308 -> 0 | D21: =Recetas!G310 -> 0 | E21: Grs | F21: =Recetas!G321 -> 0 | G21: =Recetas!G308 -> 0 | H21: =IFERROR(K21-F21,0) -> 0 | I21: =IFERROR(K21/F21,0) -> 0 | K21: =IF(G21="","",IF($L$2="Responsable inscripto",G21/1.21,G21)) -> 0

Sheet Mermas por producto
A1: Insumo | B1: Porcentaje
A2: Aceite de oliva | B2: 0
A3: Aceite de sesamo | B3: 0
A4: Aceite mezcla | B4: 0
A5: Aceite para freir | B5: 0.05
A6: Aceitunas descarozadas | B6: 0.25
A7: Acelga | B7: 0.4
A8: Aceto balsamico | B8: 0
A9: Achicoria | B9: 0.11
A10: Agua | B10: 0
A11: Agua tonica | B11: 0
A12: Ajo | B12: 0.23
A13: Ajo pasta | B13: 0.005
... A281: Zuccini | B281: 0.28
A282: ='Insumos '!A284 -> 0
A283: ='Insumos '!A285 -> 0
A284: ='Insumos '!A286 -> 0
A285: ='Insumos '!A287 -> 0
A286: ='Insumos '!A288 -> 0
A287: ='Insumos '!A289 -> 0
A288: ='Insumos '!A290 -> 0
A289: ='Insumos '!A291 -> 0
A290: ='Insumos '!A292 -> 0
A291: ='Insumos '!A293 -> 0
A292: ='Insumos '!A294 -> 0
A293: ='Insumos '!A295 -> 0
... A311: ='Insumos '!A313 -> 0
A312: Pan burger | B312: 0.05
A313: Vacuno (Picada) | B313: 0.05

Sheet Control de desperdicio 
A1: Fecha (DD/MM/AAAA) | B1: Mes | C1: Producto ( que producto de la carta o insumo) | D1: Cantidad en gramos (o unidades) | E1: Costo por gramo | F1: Costo asumido | G1: Motivo del desperdicio
B2: =IF(A2="", "", PROPER(TEXT(A2, "MMMM"))) | E2: =IFERROR(VLOOKUP(C2,'Insumos '!$A$2:$G$313,7,0),0) -> 0 | F2: =D2*E2 -> 0
B3: =IF(A3="", "", PROPER(TEXT(A3, "MMMM"))) | E3: =IFERROR(VLOOKUP(C3,'Insumos '!$A$2:$G$313,7,0),0) -> 0 | F3: =D3*E3 -> 0
B4: =IF(A4="", "", PROPER(TEXT(A4, "MMMM"))) | E4: =IFERROR(VLOOKUP(C4,'Insumos '!$A$2:$G$313,7,0),0) -> 0 | F4: =D4*E4 -> 0
B5: =IF(A5="", "", PROPER(TEXT(A5, "MMMM"))) | E5: =IFERROR(VLOOKUP(C5,'Insumos '!$A$2:$G$313,7,0),0) -> 0 | F5: =D5*E5 -> 0
B6: =IF(A6="", "", PROPER(TEXT(A6, "MMMM"))) | E6: =IFERROR(VLOOKUP(C6,'Insumos '!$A$2:$G$313,7,0),0) -> 0 | F6: =D6*E6 -> 0
B7: =IF(A7="", "", PROPER(TEXT(A7, "MMMM"))) | E7: =IFERROR(VLOOKUP(C7,'Insumos '!$A$2:$G$313,7,0),0) -> 0 | F7: =D7*E7 -> 0
B8: =IF(A8="", "", PROPER(TEXT(A8, "MMMM"))) | E8: =IFERROR(VLOOKUP(C8,'Insumos '!$A$2:$G$313,7,0),0) -> 0 | F8: =D8*E8 -> 0
B9: =IF(A9="", "", PROPER(TEXT(A9, "MMMM"))) | E9: =IFERROR(VLOOKUP(C9,'Insumos '!$A$2:$G$313,7,0),0) -> 0 | F9: =D9*E9 -> 0
B10: =IF(A10="", "", PROPER(TEXT(A10, "MMMM"))) | E10: =IFERROR(VLOOKUP(C10,'Insumos '!$A$2:$G$313,7,0),0) -> 0 | F10: =D10*E10 -> 0
B11: =IF(A11="", "", PROPER(TEXT(A11, "MMMM"))) | E11: =IFERROR(VLOOKUP(C11,'Insumos '!$A$2:$G$313,7,0),0) -> 0 | F11: =D11*E11 -> 0
B12: =IF(A12="", "", PROPER(TEXT(A12, "MMMM"))) | E12: =IFERROR(VLOOKUP(C12,'Insumos '!$A$2:$G$313,7,0),0) -> 0 | F12: =D12*E12 -> 0
B13: =IF(A13="", "", PROPER(TEXT(A13, "MMMM"))) | E13: =IFERROR(VLOOKUP(C13,'Insumos '!$A$2:$G$313,7,0),0) -> 0 | F13: =D13*E13 -> 0
... B387: =IF(A387="", "", PROPER(TEXT(A387, "MMMM"))) | E387: =IFERROR(VLOOKUP(C387,'Insumos '!$A$2:$G$313,7,0),0) -> 0 | F387: =D387*E387 -> 0
